<?xml version="1.0"?>
<robot name=  "Robot" xmlns:xacro="http://www.ros.org/wiki/xacro">

    <material name="Green">
        <color rgba="0.4 0.5 0.0 1"/>
    </material>

    <material name="Blue">
        <color rgba="0.4 0.5 0.0 1"/>
    </material>

    <link name = "base_link">
        <visual>
            <geometry>
                <box size= "0.6 0.4 0.2" />
            </geometry>
            <origin xyz="0 0 0.1" rpy="0 0 0"/>
            <material name="Breen" />
        </visual>
    </link>

    <link name="Right_wheel">
        <visual>
            <geometry>
                <cylinder radius="0.1" length="0.05"/>
            </geometry>
            <origin xyz="0.0 0.0 0.0" rpy="1.57 0.0 0.0"/>
            <material name="Blue"/>
        </visual>
    </link>

    <link name="Left_wheel">
        <visual>
            <geometry>
                <cylinder radius="0.1" length="0.05"/>
            </geometry>
            <origin xyz="0.0 0.0 0.0" rpy="1.57 0.0 0.0"/>
            <material name="Blue"/>
        </visual>
    </link>

    <link name="Caster_wheel">
        <visual>
            <geometry>
                <sphere radius="0.05"/>
            </geometry>
            <origin xyz="0.0 0.0 0.0" rpy="0.0 0.0 0.0"/>
        </visual>
    </link>

    <link name="base_footprint"/>

    <joint name="Right_wheel_Joint" type="revolute">
        <origin xyz="-0.15 -0.225 0.0" rpy="0.0 0.0 0.0"/>
        <parent link="base_link"/>
        <child link="Right_wheel"/>
        <axis xyz="0.0 1.0 0.0"/>
        <limit lower="-3.14" upper="3.14" effort="100" velocity="100"/>
    </joint>

    <joint name="Left_wheel_Joint" type="revolute">
        <origin xyz="-0.15 0.225 0.0" rpy="0.0 0.0 0.0"/>
        <parent link="base_link"/>
        <child link="Left_wheel"/>
        <axis xyz="0.0 -1.0 0.0"/>
        <limit lower="-3.14" upper="3.14" effort="100" velocity="100"/>
    </joint>

    <joint name="base_caster_wheel_joint" type="fixed">
        <origin xyz="0.2 0.0 -0.05"/>
        <parent link="base_link"/>
        <child link="Caster_wheel"/>
    </joint>
    <joint name="base_joint" type="fixed">
        <origin xyz="0.0 0.0 -0.1" rpy="0.0 0.0 0.0"/>
        <parent link="base_link"/>
        <child link="base_footprint"/>
    </joint>

</robot>